{"trial_id": "0", "hyperparameters": {"space": [{"class_name": "Choice", "config": {"name": "optimizer", "default": "adadelta", "conditions": [], "values": ["adadelta", "SDG", "adagrad"], "ordered": false}}], "values": {"optimizer": "SDG"}}, "metrics": {"metrics": {}}, "score": null, "best_step": 0, "status": "FAILED", "message": "Traceback (most recent call last):\n  File \"C:\\Users\\Administrator\\AppData\\Local\\Programs\\Python\\Python311\\Lib\\site-packages\\keras_tuner\\src\\engine\\base_tuner.py\", line 273, in _try_run_and_update_trial\n    self._run_and_update_trial(trial, *fit_args, **fit_kwargs)\n  File \"C:\\Users\\Administrator\\AppData\\Local\\Programs\\Python\\Python311\\Lib\\site-packages\\keras_tuner\\src\\engine\\base_tuner.py\", line 238, in _run_and_update_trial\n    results = self.run_trial(trial, *fit_args, **fit_kwargs)\n              ^^^^^^^^^^^^^^^^^^^^^^^^^^^^^^^^^^^^^^^^^^^^^^\n  File \"C:\\Users\\Administrator\\AppData\\Local\\Programs\\Python\\Python311\\Lib\\site-packages\\keras_tuner\\src\\engine\\tuner.py\", line 314, in run_trial\n    obj_value = self._build_and_fit_model(trial, *args, **copied_kwargs)\n                ^^^^^^^^^^^^^^^^^^^^^^^^^^^^^^^^^^^^^^^^^^^^^^^^^^^^^^^^\n  File \"C:\\Users\\Administrator\\AppData\\Local\\Programs\\Python\\Python311\\Lib\\site-packages\\keras_tuner\\src\\engine\\tuner.py\", line 232, in _build_and_fit_model\n    model = self._try_build(hp)\n            ^^^^^^^^^^^^^^^^^^^\n  File \"C:\\Users\\Administrator\\AppData\\Local\\Programs\\Python\\Python311\\Lib\\site-packages\\keras_tuner\\src\\engine\\tuner.py\", line 164, in _try_build\n    model = self._build_hypermodel(hp)\n            ^^^^^^^^^^^^^^^^^^^^^^^^^^\n  File \"C:\\Users\\Administrator\\AppData\\Local\\Programs\\Python\\Python311\\Lib\\site-packages\\keras_tuner\\src\\engine\\tuner.py\", line 155, in _build_hypermodel\n    model = self.hypermodel.build(hp)\n            ^^^^^^^^^^^^^^^^^^^^^^^^^\n  File \"C:\\Users\\Administrator\\AppData\\Local\\Temp\\ipykernel_11284\\3686439897.py\", line 22, in mydef\n    model1.compile(optimizer = optimizers, loss = 'SparseCategoricalCrossentropy', metrics = ['accuracy'])\n  File \"C:\\Users\\Administrator\\AppData\\Local\\Programs\\Python\\Python311\\Lib\\site-packages\\keras\\src\\utils\\traceback_utils.py\", line 70, in error_handler\n    raise e.with_traceback(filtered_tb) from None\n  File \"C:\\Users\\Administrator\\AppData\\Local\\Programs\\Python\\Python311\\Lib\\site-packages\\keras\\src\\saving\\legacy\\serialization.py\", line 365, in class_and_config_for_serialized_keras_object\n    raise ValueError(\nValueError: Unknown optimizer: 'SDG'. Please ensure you are using a `keras.utils.custom_object_scope` and that this object is included in the scope. See https://www.tensorflow.org/guide/keras/save_and_serialize#registering_the_custom_object for details.\n"}